{"errorMessage": "An error occurred (ProvisionedThroughputExceededException) when calling the UpdateItem operation (reached max retries: 9): The level of configured provisioned throughput for the table was exceeded. Consider increasing your provisioning level with the UpdateTable API.", "errorType": "ProvisionedThroughputExceededException", "stackTrace": [["/var/task/lambda_function.py", 41, "lambda_handler", "processContentAndSave(table, content)"], ["/var/task/lambda_function.py", 113, "processContentAndSave", "':track': row_data['track'],"], ["/var/runtime/boto3/resources/factory.py", 520, "do_action", "response = action(self, *args, **kwargs)"], ["/var/runtime/boto3/resources/action.py", 83, "__call__", "response = getattr(parent.meta.client, operation_name)(**params)"], ["/var/runtime/botocore/client.py", 314, "_api_call", "return self._make_api_call(operation_name, kwargs)"], ["/var/runtime/botocore/client.py", 612, "_make_api_call", "raise error_class(parsed_response, operation_name)"]]}